<?xml version="1.0" encoding="utf-8"?>

<robot xmlns:xacro="http://www.ros.org/wiki/xacro" name="Rover_V3_URDF">

  <!-- Included xacro files-->
  <xacro:include filename="colors.xacro" />
  <xacro:include filename="gazebo_control.xacro" />

  <!-- Base Link-->
  <link name="base_link">
  </link>

  <!-- Rear Chassis -->
  <link name="rear_chassis">

    <inertial>
      <origin
        xyz="-0.0066057 -0.00049628 0.2574"
        rpy="0 0 0" />
      <mass
        value="219.28" />
      <inertia
        ixx="9.64"
        ixy="-3.8334E-05"
        ixz="-0.01642"
        iyy="15.348"
        iyz="-3.226E-05"
        izz="18.442" />
    </inertial>

    <visual>
      <origin
        xyz="0 0 0"
        rpy="0 0 0" />
      <geometry>
        <mesh
          filename="$(find mofaro)/meshes/rear_chassis.STL" />
      </geometry>
      <material
        name="green" />
    </visual>

    <collision>
      <origin
        xyz="0 0 0"
        rpy="0 0 0" />
      <geometry>
        <mesh
          filename="$(find mofaro)/meshes/rear_chassis.STL" />
      </geometry>
    </collision>

  </link>

  <gazebo reference="rear_chassis">
		<material>Gazebo/green</material>
	</gazebo>


  <!-- Rear Left Wheel -->
  <link name="rear_left_wheel">

    <inertial>
      <origin
        xyz="3.7371E-09 -9.7686E-10 -0.073056"
        rpy="0 0 0" />
      <mass
        value="25.916" />
      <inertia
        ixx="0.18093"
        ixy="-3.7773E-08"
        ixz="-6.6434E-09"
        iyy="0.18093"
        iyz="-4.5415E-08"
        izz="0.32073" />
    </inertial>

    <visual>
      <origin
        xyz="0 0 0"
        rpy="0 0 0" />
      <geometry>
        <mesh
          filename="$(find mofaro)/meshes/rear_left_wheel.STL" />
      </geometry>
      <material
        name="black" />
    </visual>

    <collision>
      <origin
        xyz="0 0 0"
        rpy="0 0 0" />
      <geometry>
        <mesh
          filename="$(find mofaro)/meshes/rear_left_wheel.STL" />
      </geometry>
    </collision>

  </link>

  <joint
    name="rear_left_wheel_joint"
    type="continuous">
    <origin
      xyz="-0.075 0.345 -0.525"
      rpy="1.5708 0 0" />
    <parent
      link="rear_chassis" />
    <child
      link="rear_left_wheel" />
    <axis
      xyz="0 0 1" />
    <limit
      lower="0"
      upper="0"
      effort="1000"
      velocity="20.944" />
    <calibration
      rising="0"
      falling="0" />
    <dynamics
      damping="0"
      friction="0" />
    <safety_controller
      soft_upper_limit="0"
      soft_lower_limit="0"
      k_position="0"
      k_velocity="0" />
  </joint>

  <gazebo reference="rear_left_wheel">
		<material>Gazebo/black</material>
	</gazebo>


  <!-- Rear Right Wheel -->
  <link name="rear_right_wheel">

    <inertial>
      <origin
        xyz="4.269E-09 -2.038E-10 0.072994"
        rpy="0 0 0" />
      <mass
        value="25.916" />
      <inertia
        ixx="0.18093"
        ixy="-7.6339E-08"
        ixz="1.3697E-08"
        iyy="0.18093"
        iyz="4.5127E-08"
        izz="0.32073" />
    </inertial>

    <visual>
      <origin
        xyz="0 0 0"
        rpy="0 0 0" />
      <geometry>
        <mesh
          filename="$(find mofaro)/meshes/rear_right_wheel.STL" />
      </geometry>
      <material
        name="black" />
    </visual>

    <collision>
      <origin
        xyz="0 0 0"
        rpy="0 0 0" />
      <geometry>
        <mesh
          filename="$(find mofaro)/meshes/rear_right_wheel.STL" />
      </geometry>
    </collision>

  </link>

  <joint
    name="rear_right_wheel_joint"
    type="continuous">
    <origin
      xyz="-0.075 -0.345 -0.525"
      rpy="1.5708 0 0" />
    <parent
      link="rear_chassis" />
    <child
      link="rear_right_wheel" />
    <axis
      xyz="0 0 -1" />
    <limit
      lower="0"
      upper="0"
      effort="1000"
      velocity="20.944" />
    <calibration
      rising="0"
      falling="0" />
    <dynamics
      damping="0"
      friction="0" />
    <safety_controller
      soft_upper_limit="0"
      soft_lower_limit="0"
      k_position="0"
      k_velocity="0" />
  </joint>

  <gazebo reference="rear_right_wheel">
		<material>Gazebo/black</material>
	</gazebo>


  <!-- Yaw Roll -->
  <link name="yaw_roll">

    <inertial>
      <origin
        xyz="0.17123 -0.014607 -4.3195E-10"
        rpy="0 0 0" />
      <mass
        value="19.626" />
      <inertia
        ixx="0.14723"
        ixy="-0.0086497"
        ixz="1.7382E-12"
        iyy="0.17956"
        iyz="2.8608E-10"
        izz="0.12651" />
    </inertial>

    <visual>
      <origin
        xyz="0 0 0"
        rpy="0 0 0" />
      <geometry>
        <mesh
          filename="$(find mofaro)/meshes/yaw_roll.STL" />
      </geometry>
      <material
        name="orange" />
    </visual>

    <collision>
      <origin
        xyz="0 0 0"
        rpy="0 0 0" />
      <geometry>
        <mesh
          filename="$(find mofaro)/meshes/yaw_roll.STL" />
      </geometry>
    </collision>

  </link>

  <joint
    name="yaw_roll_joint"
    type="revolute">
    <origin
      xyz="0.72 0 0"
      rpy="1.5708 0 0" />
    <parent
      link="rear_chassis" />
    <child
      link="yaw_roll" />
    <axis
      xyz="-1 0 0" />
    <limit
      lower="-0.7854"
      upper="0.7854"
      effort="0"
      velocity="0" />
    <calibration
      rising="0"
      falling="0" />
    <dynamics
      damping="0"
      friction="0" />
    <safety_controller
      soft_upper_limit="0"
      soft_lower_limit="0"
      k_position="0"
      k_velocity="0" />
  </joint>

  <gazebo reference="yaw_roll">
		<material>Gazebo/orange</material>
	</gazebo>


  <!-- Fore Chassis -->
  <link name="fore_chassis">

    <inertial>
      <origin
        xyz="0.5416 0.043239 -0.00077548"
        rpy="0 0 0" />
      <mass
        value="122.92" />
      <inertia
        ixx="1.7307"
        ixy="-0.026045"
        ixz="2.9006E-07"
        iyy="3.2078"
        iyz="4.871E-07"
        izz="3.0763" />
    </inertial>

    <visual>
      <origin
        xyz="0 0 0"
        rpy="0 0 0" />
      <geometry>
        <mesh
          filename="$(find mofaro)/meshes/fore_chassis.STL" />
      </geometry>
      <material
        name="green" />
    </visual>

    <collision>
      <origin
        xyz="0 0 0"
        rpy="0 0 0" />
      <geometry>
        <mesh
          filename="$(find mofaro)/meshes/fore_chassis.STL" />
      </geometry>
    </collision>

  </link>

  <joint
    name="fore_chassis_joint"
    type="revolute">
    <origin
      xyz="0.25 0 0"
      rpy="0 0 0" />
    <parent
      link="yaw_roll" />
    <child
      link="fore_chassis" />
    <axis
      xyz="0 -0.99683 0.079557" />
    <limit
      lower="-0.7854"
      upper="0.7854"
      effort="758.15"
      velocity="0.0093313" />
    <calibration
      rising="0"
      falling="0" />
    <dynamics
      damping="0"
      friction="0" />
    <safety_controller
      soft_upper_limit="0"
      soft_lower_limit="0"
      k_position="0"
      k_velocity="0" />
  </joint>

  <gazebo reference="fore_chassis">
		<material>Gazebo/green</material>
	</gazebo>


  <!-- Fore Left Wheel -->
  <link name="fore_left_wheel">

    <inertial>
      <origin
        xyz="3.7121E-09 -9.6784E-10 -0.073056"
        rpy="0 0 0" />
      <mass
        value="25.916" />
      <inertia
        ixx="0.18093"
        ixy="-3.8285E-08"
        ixz="-7.7539E-09"
        iyy="0.18093"
        iyz="-4.4665E-08"
        izz="0.32073" />
    </inertial>

    <visual>
      <origin
        xyz="0 0 0"
        rpy="0 0 0" />
      <geometry>
        <mesh
          filename="$(find mofaro)/meshes/fore_left_wheel.STL" />
      </geometry>
      <material
        name="black" />
    </visual>

    <collision>
      <origin
        xyz="0 0 0"
        rpy="0 0 0" />
      <geometry>
        <mesh
          filename="$(find mofaro)/meshes/fore_left_wheel.STL" />
      </geometry>
    </collision>\ </link>

  <joint
    name="fore_left_wheel_joint"
    type="continuous">
    <origin
      xyz="0.67 -0.525 -0.345"
      rpy="0 0 0.013173" />
    <parent
      link="fore_chassis" />
    <child
      link="fore_left_wheel" />
    <axis
      xyz="0 0 1" />
    <limit
      effort="1000"
      velocity="20.944" />
    <calibration
      rising="0"
      falling="0" />
    <dynamics
      damping="0"
      friction="0" />
    <safety_controller
      soft_upper_limit="0"
      soft_lower_limit="0"
      k_position="0"
      k_velocity="0" />
  </joint>

  <gazebo reference="fore_left_wheel">
		<material>Gazebo/black</material>
	</gazebo>


  <!-- Fore Right Wheel -->
  <link name="fore_right_wheel">

    <inertial>
      <origin
        xyz="4.2708E-09 -2.0452E-10 0.072994"
        rpy="0 0 0" />
      <mass
        value="25.916" />
      <inertia
        ixx="0.18093"
        ixy="-7.5308E-08"
        ixz="1.4683E-08"
        iyy="0.18093"
        iyz="4.388E-08"
        izz="0.32073" />
    </inertial>

    <visual>
      <origin
        xyz="0 0 0"
        rpy="0 0 0" />
      <geometry>
        <mesh
          filename="$(find mofaro)/meshes/fore_right_wheel.STL" />
      </geometry>
      <material
        name="black" />
    </visual>

    <collision>
      <origin
        xyz="0 0 0"
        rpy="0 0 0" />
      <geometry>
        <mesh
          filename="$(find mofaro)/meshes/fore_right_wheel.STL" />
      </geometry>
    </collision>

  </link>

  <joint
    name="fore_right_wheel_joint"
    type="continuous">
    <origin
      xyz="0.67 -0.525 0.345"
      rpy="0 0 0" />
    <parent
      link="fore_chassis" />
    <child
      link="fore_right_wheel" />
    <axis
      xyz="0 0 -1" />
    <limit
      effort="1000"
      velocity="20.944" />
    <calibration
      rising="0"
      falling="0" />
    <dynamics
      damping="0"
      friction="0" />
    <safety_controller
      soft_upper_limit="0"
      soft_lower_limit="0"
      k_position="0"
      k_velocity="0" />
  </joint>

  <gazebo reference="fore_right_wheel">
		<material>Gazebo/black</material>
	</gazebo>


  <!-- Right Boom -->
  <link name="right_boom">

    <inertial>
      <origin
        xyz="-0.94617 0.077772 -0.0015148"
        rpy="0 0 0" />
      <mass
        value="4.2764" />
      <inertia
        ixx="0.0026347"
        ixy="-0.006461"
        ixz="2.8516E-08"
        iyy="0.66786"
        iyz="-5.4132E-10"
        izz="0.66976" />
    </inertial>

    <visual>
      <origin
        xyz="0 0 0"
        rpy="0 0 0" />
      <geometry>
        <mesh
          filename="$(find mofaro)/meshes/right_boom.STL" />
      </geometry>
      <material
        name="blue" />
    </visual>

    <collision>
      <origin
        xyz="0 0 0"
        rpy="0 0 0" />
      <geometry>
        <mesh
          filename="$(find mofaro)/meshes/right_boom.STL" />
      </geometry>
    </collision>

  </link>

  <joint
    name="right_boom_joint"
    type="revolute">
    <origin
      xyz="-0.8895 -0.51 -0.275"
      rpy="3.1416 1.5708 0" />
    <parent
      link="rear_chassis" />
    <child
      link="right_boom" />
    <axis
      xyz="0 0 0" />
    <limit
      lower="0"
      upper="3.14"
      effort="6000"
      velocity="0.027" />
    <calibration
      rising="0"
      falling="0" />
    <dynamics
      damping="0"
      friction="0" />
    <safety_controller
      soft_upper_limit="0"
      soft_lower_limit="0"
      k_position="0"
      k_velocity="0" />
  </joint>

  <gazebo reference="right_boom">
		<material>Gazebo/blue</material>
	</gazebo>


  <!-- Left Boom -->
  <link name="left_boom">

    <inertial>
      <origin
        xyz="-0.94617 0.077772 0.0015147"
        rpy="0 0 0" />
      <mass
        value="4.2764" />
      <inertia
        ixx="0.0026347"
        ixy="-0.006461"
        ixz="2.8521E-08"
        iyy="0.66786"
        iyz="-5.4178E-10"
        izz="0.66976" />
    </inertial>

    <visual>
      <origin
        xyz="0 0 0"
        rpy="0 0 0" />
      <geometry>
        <mesh
          filename="$(find mofaro)/meshes/left_boom.STL" />
      </geometry>
      <material
        name="black" />
    </visual>

    <collision>
      <origin
        xyz="0 0 0"
        rpy="0 0 0" />
      <geometry>
        <mesh
          filename="$(find mofaro)/meshes/left_boom.STL" />
      </geometry>
    </collision>

  </link>

  <joint
    name="left_boom_joint"
    type="revolute">
    <origin
      xyz="-0.8895 0.51 -0.275"
      rpy="0 1.5708 0" />
    <parent
      link="rear_chassis" />
    <child
      link="left_boom" />
    <axis
      xyz="0 0 0" />
    <limit
      lower="0"
      upper="3.14"
      effort="6000"
      velocity="0.027" />
    <calibration
      rising="0"
      falling="0" />
    <dynamics
      damping="0"
      friction="0" />
    <safety_controller
      soft_upper_limit="0"
      soft_lower_limit="0"
      k_position="0"
      k_velocity="0" />
  </joint>

  <gazebo reference="left_boom">
		<material>Gazebo/blue</material>
	</gazebo>


</robot>